Workbook

Sheet MALANG
A1: REKAP PENJUALAN SALES AJM APRIL 2026
A2: No. | B2: DATE | C2: PLANT | D2: SALES | E2: CUSTOMER | F2: PROYEK | G2: VOL | H2: MUTU | I2: DEAL | J2: PPN | K2: HARGA + PPN | L2: TOTAL DEAL | M2: AJM | N2: PPN | O2: HARGA + PPN | P2: TOTAL AJM | Q2: BUY IN | R2: PPN | S2: HARGA + PPN | T2: TOTAL BUY IN | U2: FEE | V2: MARGIN/m3 | W2: TOTAL MARGIN | X2: SHARE MARGIN | Y2: TOTAL SHARE
A3: 1 | B3: 46114 | C3: Malang | D3: AJM | E3: Andreas | F3: GPDI ANUGERAH TANGGGUNG TUREN | G3: 8 | H3: K250 | I3: 880000 | J3: =I3*11% -> 96800 | K3: =I3+J3 -> 976800 | L3: =K3*G3 -> 7814400 | M3: 880000 | N3: =M3*11% -> 96800 | O3: =M3+N3 -> 976800 | P3: =O3*G3 -> 7814400 | Q3: 760000 | R3: =Q3*11% -> 83600 | S3: =Q3+R3 -> 843600 | T3: =S3*G3 -> 6748800 | U3: =15000*12 -> 180000 | V3: =M3-Q3 -> 120000 | W3: =(M3-Q3)*G3 -> 960000 | X3: 0 | Y3: =G3*X3 -> 0
A4: 2 | B4: 46123 | C4: Malang | D4: Kusbiantoro | E4: PT. Amzak | F4: PLN Kebon Agung Malang | G4: 4 | H4: K350 | I4: 792792.79 | J4: =I4*11% -> 87207.207 | K4: =I4+J4 -> 880000 | L4: =K4*G4 -> 3520000 | M4: 770000 | N4: =M4*11% -> 84700 | O4: =M4+N4 -> 854700 | P4: =O4*G4 -> 3418800 | Q4: 740000 | R4: =Q4*11% -> 81400 | S4: =Q4+R4 -> 821400 | T4: =S4*G4 -> 3285600 | U4: =(I4-M4)*G4 -> 91171.171 | V4: =M4-Q4 -> 30000 | W4: =(M4-Q4)*G4 -> 120000 | X4: 0 | Y4: =G4*X4 -> 0
A5: 3 | B5: 46128 | C5: Malang | D5: Kusbiantoro | E5: PT. Amzak | F5: PLN Kebon Agung Malang | G5: 5 | H5: K350 | I5: 792792.79 | J5: =I5*11% -> 87207.207 | K5: =I5+J5 -> 880000 | L5: =K5*G5 -> 4400000 | M5: 770000 | N5: =M5*11% -> 84700 | O5: =M5+N5 -> 854700 | P5: =O5*G5 -> 4273500 | Q5: 740000 | R5: =Q5*11% -> 81400 | S5: =Q5+R5 -> 821400 | T5: =S5*G5 -> 4107000 | U5: =(I5-M5)*G5 -> 113963.96 | V5: =M5-Q5 -> 30000 | W5: =(M5-Q5)*G5 -> 150000 | X5: 0 | Y5: =G5*X5 -> 0
A6: 4 | B6: 46132 | C6: Malang | D6: AJM | E6: Bpk. Yusuf (non ppn) | F6: 3PV4+V38 Dengkol, Kabupaten Malang, Jawa Timur | G6: 13 | H6: K300 | I6: 780000 | J6: =I6*11% -> 85800 | K6: =I6+J6 -> 865800 | L6: =K6*G6 -> 11255400 | M6: 780000 | N6: =M6*11% -> 85800 | O6: =M6+N6 -> 865800 | P6: =O6*G6 -> 11255400 | Q6: 750000 | R6: =Q6*11% -> 82500 | S6: =Q6+R6 -> 832500 | T6: =S6*G6 -> 10822500 | U6: =(I6-M6)*G6 -> 0 | V6: =M6-Q6 -> 30000 | W6: =(M6-Q6)*G6 -> 390000 | X6: 0 | Y6: =G6*X6 -> 0
A7: 5 | B7: 46137 | C7: Malang | D7: Kusbiantoro | E7: PT. Amzak | F7: PLN Kebon Agung Malang | G7: 7 | H7: K350 | I7: 792792.79 | J7: =I7*11% -> 87207.207 | K7: =I7+J7 -> 880000 | L7: =K7*G7 -> 6160000 | M7: 770000 | N7: =M7*11% -> 84700 | O7: =M7+N7 -> 854700 | P7: =O7*G7 -> 5982900 | Q7: 740000 | R7: =Q7*11% -> 81400 | S7: =Q7+R7 -> 821400 | T7: =S7*G7 -> 5749800 | U7: =(I7-M7)*G7 -> 159549.55 | V7: =M7-Q7 -> 30000 | W7: =(M7-Q7)*G7 -> 210000 | X7: 0 | Y7: =G7*X7 -> 0
A8: 6 | B8: 46141 | C8: Malang | D8: Kusbiantoro | E8: Bpk Permadi | F8: Tandon Air PT. Rimba Kencana | G8: 16 | H8: K400NFA | I8: 801801.8 | J8: =I8*11% -> 88198.198 | K8: =I8+J8 -> 890000 | L8: =K8*G8 -> 14240000 | M8: 780000 | N8: =M8*11% -> 85800 | O8: =M8+N8 -> 865800 | P8: =O8*G8 -> 13852800 | Q8: 760000 | R8: =Q8*11% -> 83600 | S8: =Q8+R8 -> 843600 | T8: =S8*G8 -> 13497600 | U8: =(I8-M8)*G8 -> 348828.83 | V8: =M8-Q8 -> 20000 | W8: =(M8-Q8)*G8 -> 320000 | X8: 0 | Y8: =G8*X8 -> 0
A9: 7 | C9: Malang | J9: =I9*11% -> 0 | K9: =I9+J9 -> 0 | L9: =K9*G9 -> 0 | N9: =M9*11% -> 0 | O9: =M9+N9 -> 0 | P9: =O9*G9 -> 0 | R9: =Q9*11% -> 0 | S9: =Q9+R9 -> 0 | T9: =S9*G9 -> 0 | U9: =(I9-M9)*G9 -> 0 | V9: =M9-Q9 -> 0 | W9: =(M9-Q9)*G9 -> 0 | X9: 0 | Y9: =G9*X9 -> 0
A10: 8 | C10: Malang | J10: =I10*11% -> 0 | K10: =I10+J10 -> 0 | L10: =K10*G10 -> 0 | N10: =M10*11% -> 0 | O10: =M10+N10 -> 0 | P10: =O10*G10 -> 0 | R10: =Q10*11% -> 0 | S10: =Q10+R10 -> 0 | T10: =S10*G10 -> 0 | U10: =(I10-M10)*G10 -> 0 | V10: =M10-Q10 -> 0 | W10: =(M10-Q10)*G10 -> 0 | X10: 0 | Y10: =G10*X10 -> 0
A11: 9 | C11: Malang | J11: =I11*11% -> 0 | K11: =I11+J11 -> 0 | L11: =K11*G11 -> 0 | N11: =M11*11% -> 0 | O11: =M11+N11 -> 0 | P11: =O11*G11 -> 0 | R11: =Q11*11% -> 0 | S11: =Q11+R11 -> 0 | T11: =S11*G11 -> 0 | U11: =(I11-M11)*G11 -> 0 | V11: =M11-Q11 -> 0 | W11: =(M11-Q11)*G11 -> 0 | X11: 0 | Y11: =G11*X11 -> 0
A12: 10 | C12: Malang | J12: =I12*11% -> 0 | K12: =I12+J12 -> 0 | L12: =K12*G12 -> 0 | N12: =M12*11% -> 0 | O12: =M12+N12 -> 0 | P12: =O12*G12 -> 0 | R12: =Q12*11% -> 0 | S12: =Q12+R12 -> 0 | T12: =S12*G12 -> 0 | U12: =(I12-M12)*G12 -> 0 | V12: =M12-Q12 -> 0 | W12: =(M12-Q12)*G12 -> 0 | X12: 0 | Y12: =G12*X12 -> 0
B15: TOTAL | G15: =SUM(G3:G14) -> 53 | L15: =SUM(L3:L14) -> 47389800 | P15: =SUM(P3:P14) -> 46597800 | T15: =SUM(T3:T14) -> 44211300 | U15: =SUM(U3:U14) -> 893513.51 | W15: =SUM(W3:W14) -> 2150000 | X15: =W15/G15 -> 40566.038 | Y15: =SUM(Y3:Y14) -> 0

Sheet GEMPOL
A1: =MALANG!A1 -> REKAP PENJUALAN SALES AJM APRIL 2026
A2: No. | B2: DATE | C2: PLANT | D2: SALES | E2: CUSTOMER | F2: PROYEK | G2: VOL | H2: MUTU | I2: DEAL | J2: PPN | K2: HARGA + PPN | L2: TOTAL DEAL | M2: AJM | N2: PPN | O2: HARGA + PPN | P2: TOTAL AJM | Q2: BUY IN | R2: PPN | S2: HARGA + PPN | T2: TOTAL BUY IN | U2: FEE | V2: MARGIN/m3 | W2: TOTAL MARGIN | X2: SHARE MARGIN | Y2: TOTAL SHARE
A3: 1 | B3: 46116 | C3: Gempol | D3: AJM | E3: Wisnu Wardono | F3: PT. Rajawali Megah Semesta Jl. Rangkah Kidul, Kec. Sidoarjo | G3: 22 | H3: K300 | I3: 770000 | J3: =I3*11% -> 84700 | K3: =I3+J3 -> 854700 | L3: =K3*G3 -> 18803400 | M3: 770000 | N3: =M3*11% -> 84700 | O3: =M3+N3 -> 854700 | P3: =O3*G3 -> 18803400 | Q3: 700000 | R3: =Q3*11% -> 77000 | S3: =Q3+R3 -> 777000 | T3: =S3*G3 -> 17094000 | U3: =(I3-M3)*G3 -> 0 | V3: =M3-Q3 -> 70000 | W3: =G3*V3 -> 1540000 | X3: 0 | Y3: =G3*X3 -> 0
A4: 2 | B4: 46116 | C4: Gempol | D4: AJM | E4: PT. Persada Usaha Mandiri | F4: Gedung Cold Storage No. 168 Bangil | G4: 6 | H4: K300NFA | I4: 780000 | J4: =I4*11% -> 85800 | K4: =I4+J4 -> 865800 | L4: =K4*G4 -> 5194800 | M4: 780000 | N4: =M4*11% -> 85800 | O4: =M4+N4 -> 865800 | P4: =O4*G4 -> 5194800 | Q4: 750000 | R4: =Q4*11% -> 82500 | S4: =Q4+R4 -> 832500 | T4: =S4*G4 -> 4995000 | U4: =(I4-M4)*G4 -> 0 | V4: =M4-Q4 -> 30000 | W4: =G4*V4 -> 180000 | X4: 0 | Y4: =G4*X4 -> 0
A5: 3 | B5: 46116 | C5: Gempol | D5: Cahyono | E5: Bapak Dwi | F5: Gempol 9 | G5: 5 | H5: K225 | I5: =785000/1.11 -> 707207.21 | J5: =I5*11% -> 77792.793 | K5: =I5+J5 -> 785000 | L5: =K5*G5 -> 3925000 | M5: =760000/1.11 -> 684684.68 | N5: =M5*11% -> 75315.315 | O5: =M5+N5 -> 760000 | P5: =O5*G5 -> 3800000 | Q5: 650000 | R5: =Q5*11% -> 71500 | S5: =Q5+R5 -> 721500 | T5: =S5*G5 -> 3607500 | U5: =(I5-M5)*G5 -> 112612.61 | V5: =M5-Q5 -> 34684.685 | W5: =G5*V5 -> 173423.42 | X5: 0 | Y5: =G5*X5 -> 0
A6: 4 | B6: 46119 | C6: Gempol | D6: Cahyono | E6: Bapak Dwi | F6: Gempol 9 | G6: 5.5 | H6: K225 | I6: =785000/1.11 -> 707207.21 | J6: =I6*11% -> 77792.793 | K6: =I6+J6 -> 785000 | L6: =K6*G6 -> 4317500 | M6: =760000/1.11 -> 684684.68 | N6: =M6*11% -> 75315.315 | O6: =M6+N6 -> 760000 | P6: =O6*G6 -> 4180000 | Q6: 650000 | R6: =Q6*11% -> 71500 | S6: =Q6+R6 -> 721500 | T6: =S6*G6 -> 3968250 | U6: =(I6-M6)*G6 -> 123873.87 | V6: =M6-Q6 -> 34684.685 | W6: =G6*V6 -> 190765.77 | X6: 0 | Y6: =G6*X6 -> 0
A7: 5 | B7: 46120 | C7: Gempol | D7: AJM | E7: PT HP Metals Indonesia | F7: Ngoro Industri Persada Blok K No.2 Ngoro - Kabupaten Mojokerto | G7: 6 | H7: K350 | I7: 800000 | J7: =I7*11% -> 88000 | K7: =I7+J7 -> 888000 | L7: =K7*G7 -> 5328000 | M7: 800000 | N7: =M7*11% -> 88000 | O7: =M7+N7 -> 888000 | P7: =O7*G7 -> 5328000 | Q7: 750000 | R7: =Q7*11% -> 82500 | S7: =Q7+R7 -> 832500 | T7: =S7*G7 -> 4995000 | U7: =(I7-M7)*G7 -> 0 | V7: =M7-Q7 -> 50000 | W7: =G7*V7 -> 300000 | X7: 0 | Y7: =G7*X7 -> 0
A8: 6 | B8: 46120 | C8: Gempol | D8: Rizal | E8: PT Tri Megah Baswara | F8: PT Tri Megah Baswara | G8: 21 | H8: K350NFA | I8: 755000 | J8: =I8*11% -> 83050 | K8: =I8+J8 -> 838050 | L8: =K8*G8 -> 17599050 | M8: 755000 | N8: =M8*11% -> 83050 | O8: =M8+N8 -> 838050 | P8: =O8*G8 -> 17599050 | Q8: 725000 | R8: =Q8*11% -> 79750 | S8: =Q8+R8 -> 804750 | T8: =S8*G8 -> 16899750 | U8: =(I8-M8)*G8 -> 0 | V8: =M8-Q8 -> 30000 | W8: =G8*V8 -> 630000 | X8: 5000 | Y8: =G8*X8 -> 105000
A9: 7 | B9: 46121 | C9: Gempol | D9: Cahyono | E9: Bapak Dwi | F9: Gempol 9 | G9: 6 | H9: K225 | I9: =785000/1.11 -> 707207.21 | J9: =I9*11% -> 77792.793 | K9: =I9+J9 -> 785000 | L9: =K9*G9 -> 4710000 | M9: =760000/1.11 -> 684684.68 | N9: =M9*11% -> 75315.315 | O9: =M9+N9 -> 760000 | P9: =O9*G9 -> 4560000 | Q9: 650000 | R9: =Q9*11% -> 71500 | S9: =Q9+R9 -> 721500 | T9: =S9*G9 -> 4329000 | U9: =(I9-M9)*G9 -> 135135.14 | V9: =M9-Q9 -> 34684.685 | W9: =G9*V9 -> 208108.11 | X9: 0 | Y9: =G9*X9 -> 0
A10: 8 | B10: 46125 | C10: Gempol | D10: AJM | E10: PT Solindo Tama Jaya | F10: Dn Gesing 0 RT 00 RW 00 randu pitu | G10: 105 | H10: K350 | I10: 770000 | J10: =I10*11% -> 84700 | K10: =I10+J10 -> 854700 | L10: =K10*G10 -> 89743500 | M10: 760000 | N10: =M10*11% -> 83600 | O10: =M10+N10 -> 843600 | P10: =O10*G10 -> 88578000 | Q10: 700000 | R10: =Q10*11% -> 77000 | S10: =Q10+R10 -> 777000 | T10: =S10*G10 -> 81585000 | U10: =(I10-M10)*G10 -> 1050000 | V10: =M10-Q10 -> 60000 | W10: =G10*V10 -> 6300000 | X10: 0 | Y10: =G10*X10 -> 0
A11: 9 | B11: 46125 | C11: Gempol | D11: Cahyono | E11: Bapak Dwi | F11: Gempol 9 | G11: 15 | H11: K225 | I11: =785000/1.11 -> 707207.21 | J11: =I11*11% -> 77792.793 | K11: =I11+J11 -> 785000 | L11: =K11*G11 -> 11775000 | M11: =760000/1.11 -> 684684.68 | N11: =M11*11% -> 75315.315 | O11: =M11+N11 -> 760000 | P11: =O11*G11 -> 11400000 | Q11: 650000 | R11: =Q11*11% -> 71500 | S11: =Q11+R11 -> 721500 | T11: =S11*G11 -> 10822500 | U11: =(I11-M11)*G11 -> 337837.84 | V11: =M11-Q11 -> 34684.685 | W11: =G11*V11 -> 520270.27 | X11: 0 | Y11: =G11*X11 -> 0
A12: 10 | B12: 46125 | C12: Gempol | D12: Reyza | E12: Bapak Rahmad | F12: Kajang II, Kepulungan, Kec. Gempol, Pasuruan, Jawa Timur 67155 | G12: 7 | H12: K500 | I12: =930000/1.11 -> 837837.84 | J12: =I12*11% -> 92162.162 | K12: =I12+J12 -> 930000 | L12: =K12*G12 -> 6510000 | M12: =930000/1.11 -> 837837.84 | N12: =M12*11% -> 92162.162 | O12: =M12+N12 -> 930000 | P12: =O12*G12 -> 6510000 | Q12: 780000 | R12: =Q12*11% -> 85800 | S12: =Q12+R12 -> 865800 | T12: =S12*G12 -> 6060600 | U12: =(I12-M12)*G12 -> 0 | V12: =M12-Q12 -> 57837.838 | W12: =G12*V12 -> 404864.86 | X12: 0 | Y12: =G12*X12 -> 0
A13: 11 | B13: 46126 | C13: Gempol | D13: AJM | E13: Bpk Saipul | F13: Bakalan Purwosari Samping Saigon | G13: 4 | H13: K300 | I13: 800000 | J13: =I13*11% -> 88000 | K13: =I13+J13 -> 888000 | L13: =K13*G13 -> 3552000 | M13: 800000 | N13: =M13*11% -> 88000 | O13: =M13+N13 -> 888000 | P13: =O13*G13 -> 3552000 | Q13: 765000 | R13: =Q13*11% -> 84150 | S13: =Q13+R13 -> 849150 | T13: =S13*G13 -> 3396600 | U13: =(I13-M13)*G13 -> 0 | V13: =M13-Q13 -> 35000 | W13: =G13*V13 -> 140000 | X13: 0 | Y13: =G13*X13 -> 0
A14: 12 | B14: 46126 | C14: Gempol | D14: AJM | E14: PT HP Metals Indonesia | F14: Ngoro Industri Persada Blok K No.2 Ngoro - Kabupaten Mojokerto | G14: 7.5 | H14: K350 | I14: 800000 | J14: =I14*11% -> 88000 | K14: =I14+J14 -> 888000 | L14: =K14*G14 -> 6660000 | M14: 800000 | N14: =M14*11% -> 88000 | O14: =M14+N14 -> 888000 | P14: =O14*G14 -> 6660000 | Q14: 750000 | R14: =Q14*11% -> 82500 | S14: =Q14+R14 -> 832500 | T14: =S14*G14 -> 6243750 | U14: =(I14-M14)*G14 -> 0 | V14: =M14-Q14 -> 50000 | W14: =G14*V14 -> 375000 | X14: 0 | Y14: =G14*X14 -> 0
A15: 13 | B15: 46127 | C15: Gempol | D15: AJM | E15: Wisnu Wardono | F15: PT. Rajawali Megah Semesta Jl. Rangkah Kidul, Kec. Sidoarjo | G15: 12 | H15: K300 | I15: 770000 | J15: =I15*11% -> 84700 | K15: =I15+J15 -> 854700 | L15: =K15*G15 -> 10256400 | M15: 770000 | N15: =M15*11% -> 84700 | O15: =M15+N15 -> 854700 | P15: =O15*G15 -> 10256400 | Q15: 730000 | R15: =Q15*11% -> 80300 | S15: =Q15+R15 -> 810300 | T15: =S15*G15 -> 9723600 | U15: =(I15-M15)*G15 -> 0 | V15: =M15-Q15 -> 40000 | W15: =G15*V15 -> 480000 | X15: 0 | Y15: =G15*X15 -> 0
A16: 14 | B16: 46128 | C16: Gempol | D16: AJM | E16: Bapak Agus | F16: Panggreh, Kec. Jabon, Kabupaten Sidoarjo, Jawa Timur 61278 | G16: 8 | H16: K225 | I16: 770000 | J16: =I16*11% -> 84700 | K16: =I16+J16 -> 854700 | L16: =K16*G16 -> 6837600 | M16: 740000 | N16: =M16*11% -> 81400 | O16: =M16+N16 -> 821400 | P16: =O16*G16 -> 6571200 | Q16: 690000 | R16: =Q16*11% -> 75900 | S16: =Q16+R16 -> 765900 | T16: =S16*G16 -> 6127200 | U16: =(I16-M16)*G16 -> 240000 | V16: =M16-Q16 -> 50000 | W16: =G16*V16 -> 400000 | X16: 0 | Y16: =G16*X16 -> 0
A17: 15 | B17: 46129 | C17: Gempol | D17: Cahyono | E17: Sonokeling indah | F17: Sonokeling indah beji | G17: 16 | H17: K300 | I17: 860000 | J17: =I17*11% -> 94600 | K17: =I17+J17 -> 954600 | L17: =K17*G17 -> 15273600 | M17: 775000 | N17: =M17*11% -> 85250 | O17: =M17+N17 -> 860250 | P17: =O17*G17 -> 13764000 | Q17: 705000 | R17: =Q17*11% -> 77550 | S17: =Q17+R17 -> 782550 | T17: =S17*G17 -> 12520800 | U17: =(I17-M17)*G17 -> 1360000 | V17: =M17-Q17 -> 70000 | W17: =G17*V17 -> 1120000 | X17: 0 | Y17: =G17*X17 -> 0
A18: 16 | B18: 46130 | C18: Gempol | D18: AJM | E18: PT Solindo Tama Jaya | F18: Dn Gesing 0 RT 00 RW 00 randu pitu | G18: 75 | H18: K350 | I18: 770000 | J18: =I18*11% -> 84700 | K18: =I18+J18 -> 854700 | L18: =K18*G18 -> 64102500 | M18: 760000 | N18: =M18*11% -> 83600 | O18: =M18+N18 -> 843600 | P18: =O18*G18 -> 63270000 | Q18: 700000 | R18: =Q18*11% -> 77000 | S18: =Q18+R18 -> 777000 | T18: =S18*G18 -> 58275000 | U18: =(I18-M18)*G18 -> 750000 | V18: =M18-Q18 -> 60000 | W18: =G18*V18 -> 4500000 | X18: 0 | Y18: =G18*X18 -> 0
A19: 17 | B19: 46132 | C19: Gempol | D19: AJM | E19: PT HP Metals Indonesia | F19: Ngoro Industri Persada Blok K No.2 Ngoro - Kabupaten Mojokerto | G19: 11 | H19: K350 | I19: 800000 | J19: =I19*11% -> 88000 | K19: =I19+J19 -> 888000 | L19: =K19*G19 -> 9768000 | M19: 800000 | N19: =M19*11% -> 88000 | O19: =M19+N19 -> 888000 | P19: =O19*G19 -> 9768000 | Q19: 750000 | R19: =Q19*11% -> 82500 | S19: =Q19+R19 -> 832500 | T19: =S19*G19 -> 9157500 | U19: =(I19-M19)*G19 -> 0 | V19: =M19-Q19 -> 50000 | W19: =G19*V19 -> 550000 | X19: 0 | Y19: =G19*X19 -> 0
A20: 18 | B20: 46132 | C20: Gempol | D20: Reyza | E20: cv citra karya abadi | F20: PT. Cargill 9R99+FVV, Pejangkungan, Kec. Rembang, Pasuruan, Jawa Timur 67152 | G20: 3 | H20: K400 SP3 | I20: 1350000 | J20: =I20*11% -> 148500 | K20: =I20+J20 -> 1498500 | L20: =K20*G20 -> 4495500 | M20: 1350000 | N20: =M20*11% -> 148500 | O20: =M20+N20 -> 1498500 | P20: =O20*G20 -> 4495500 | Q20: 1300000 | R20: =Q20*11% -> 143000 | S20: =Q20+R20 -> 1443000 | T20: =S20*G20 -> 4329000 | U20: =(I20-M20)*G20 -> 0 | V20: =M20-Q20 -> 50000 | W20: =G20*V20 -> 150000 | X20: 0 | Y20: =G20*X20 -> 0
A21: 19 | B21: 46132 | C21: Gempol | D21: Cahyono | E21: Bapak Misnadi | F21: Masjid STIT muhammadiyah 2 Bangil | G21: 33 | H21: K300NFA | I21: =857000/1.11 -> 772072.07 | J21: =I21*11% -> 84927.928 | K21: =I21+J21 -> 857000 | L21: =K21*G21 -> 28281000 | M21: =857000/1.11 -> 772072.07 | N21: =M21*11% -> 84927.928 | O21: =M21+N21 -> 857000 | P21: =O21*G21 -> 28281000 | Q21: 730000 | R21: =Q21*11% -> 80300 | S21: =Q21+R21 -> 810300 | T21: =S21*G21 -> 26739900 | U21: =(I21-M21)*G21 -> 0 | V21: =M21-Q21 -> 42072.072 | W21: =G21*V21 -> 1388378.4 | X21: 0 | Y21: =G21*X21 -> 0
A22: 20 | B22: 46133 | C22: Gempol | D22: Cahyono | E22: Ibu Sari | F22: Rumah Istana Lokasi jln Ry kesiman- penanggungan pandaan | G22: 60 | H22: K300NFA | I22: =935000/1.11 -> 842342.34 | J22: =I22*11% -> 92657.658 | K22: =I22+J22 -> 935000 | L22: =K22*G22 -> 56100000 | M22: 835000 | N22: =M22*11% -> 91850 | O22: =M22+N22 -> 926850 | P22: =O22*G22 -> 55611000 | Q22: 775000 | R22: =Q22*11% -> 85250 | S22: =Q22+R22 -> 860250 | T22: =S22*G22 -> 51615000 | U22: =(I22-M22)*G22 -> 440540.54 | V22: =M22-Q22 -> 60000 | W22: =G22*V22 -> 3600000 | X22: 0 | Y22: =G22*X22 -> 0
A23: 21 | B23: 46133 | C23: Gempol | D23: AJM | E23: Bpk Erwin | F23: crusher wirabhumi sejati ngoro | G23: 19 | H23: K350 | I23: 850000 | J23: =I23*11% -> 93500 | K23: =I23+J23 -> 943500 | L23: =K23*G23 -> 17926500 | M23: 850000 | N23: =M23*11% -> 93500 | O23: =M23+N23 -> 943500 | P23: =O23*G23 -> 17926500 | Q23: 770000 | R23: =Q23*11% -> 84700 | S23: =Q23+R23 -> 854700 | T23: =S23*G23 -> 16239300 | U23: =(I23-M23)*G23 -> 0 | V23: =M23-Q23 -> 80000 | W23: =G23*V23 -> 1520000 | X23: 0 | Y23: =G23*X23 -> 0
A24: 22 | B24: 46133 | C24: Gempol | D24: Reyza | E24: Bpk Muiz | F24: Jl. Dukuhsari, Dukuhsari II, Dukuhsari, Kec. Jabon, Kabupaten Sidoarjo, Jawa Timur 61276 | G24: 27.5 | H24: K300 | I24: 800000 | J24: =I24*11% -> 88000 | K24: =I24+J24 -> 888000 | L24: =K24*G24 -> 24420000 | M24: 800000 | N24: =M24*11% -> 88000 | O24: =M24+N24 -> 888000 | P24: =O24*G24 -> 24420000 | Q24: 705000 | R24: =Q24*11% -> 77550 | S24: =Q24+R24 -> 782550 | T24: =S24*G24 -> 21520125 | U24: =(I24-M24)*G24 -> 0 | V24: =M24-Q24 -> 95000 | W24: =G24*V24 -> 2612500 | X24: 0 | Y24: =G24*X24 -> 0
A25: 23 | B25: 46134 | C25: Gempol | D25: Cahyono | E25: Ibu Sari | F25: Rumah Istana Lokasi jln Ry kesiman- penanggungan pandaan | G25: 75 | H25: K300NFA | I25: =935000/1.11 -> 842342.34 | J25: =I25*11% -> 92657.658 | K25: =I25+J25 -> 935000 | L25: =K25*G25 -> 70125000 | M25: 835000 | N25: =M25*11% -> 91850 | O25: =M25+N25 -> 926850 | P25: =O25*G25 -> 69513750 | Q25: 775000 | R25: =Q25*11% -> 85250 | S25: =Q25+R25 -> 860250 | T25: =S25*G25 -> 64518750 | U25: =(I25-M25)*G25 -> 550675.68 | V25: =M25-Q25 -> 60000 | W25: =G25*V25 -> 4500000 | X25: 0 | Y25: =G25*X25 -> 0
A26: 24 | B26: 46135 | C26: Gempol | D26: AJM | E26: PT Solindo Tama Jaya | F26: Dn Gesing 0 RT 00 RW 00 randu pitu | G26: 84 | H26: K400 | I26: 850000 | J26: =I26*11% -> 93500 | K26: =I26+J26 -> 943500 | L26: =K26*G26 -> 79254000 | M26: 840000 | N26: =M26*11% -> 92400 | O26: =M26+N26 -> 932400 | P26: =O26*G26 -> 78321600 | Q26: 750000 | R26: =Q26*11% -> 82500 | S26: =Q26+R26 -> 832500 | T26: =S26*G26 -> 69930000 | U26: =(I26-M26)*G26 -> 840000 | V26: =M26-Q26 -> 90000 | W26: =G26*V26 -> 7560000 | X26: 0 | Y26: =G26*X26 -> 0
A27: 25 | B27: 46137 | C27: Gempol | D27: AJM | E27: PT HP Metals Indonesia | F27: Ngoro Industri Persada Blok K No.2 Ngoro - Kabupaten Mojokerto | G27: 16 | H27: K350 | I27: 800000 | J27: =I27*11% -> 88000 | K27: =I27+J27 -> 888000 | L27: =K27*G27 -> 14208000 | M27: 800000 | N27: =M27*11% -> 88000 | O27: =M27+N27 -> 888000 | P27: =O27*G27 -> 14208000 | Q27: 750000 | R27: =Q27*11% -> 82500 | S27: =Q27+R27 -> 832500 | T27: =S27*G27 -> 13320000 | U27: =(I27-M27)*G27 -> 0 | V27: =M27-Q27 -> 50000 | W27: =G27*V27 -> 800000 | X27: 0 | Y27: =G27*X27 -> 0
A28: 26 | B28: 46137 | C28: Gempol | D28: Reyza | E28: Bpk Muiz | F28: Jl. Dukuhsari, Dukuhsari II, Dukuhsari, Kec. Jabon, Kabupaten Sidoarjo, Jawa Timur 61276 | G28: 31 | H28: K300 | I28: 800000 | J28: =I28*11% -> 88000 | K28: =I28+J28 -> 888000 | L28: =K28*G28 -> 27528000 | M28: 800000 | N28: =M28*11% -> 88000 | O28: =M28+N28 -> 888000 | P28: =O28*G28 -> 27528000 | Q28: 725000 | R28: =Q28*11% -> 79750 | S28: =Q28+R28 -> 804750 | T28: =S28*G28 -> 24947250 | U28: =(I28-M28)*G28 -> 0 | V28: =M28-Q28 -> 75000 | W28: =G28*V28 -> 2325000 | X28: 0 | Y28: =G28*X28 -> 0
A29: 27 | B29: 46139 | C29: Gempol | D29: Cahyono | E29: Ibu Sari | F29: Rumah Istana Lokasi jln Ry kesiman- penanggungan pandaan | G29: 90 | H29: K300NFA | I29: =935000/1.11 -> 842342.34 | J29: =I29*11% -> 92657.658 | K29: =I29+J29 -> 935000 | L29: =K29*G29 -> 84150000 | M29: 835000 | N29: =M29*11% -> 91850 | O29: =M29+N29 -> 926850 | P29: =O29*G29 -> 83416500 | Q29: 775000 | R29: =Q29*11% -> 85250 | S29: =Q29+R29 -> 860250 | T29: =S29*G29 -> 77422500 | U29: =(I29-M29)*G29 -> 660810.81 | V29: =M29-Q29 -> 60000 | W29: =G29*V29 -> 5400000 | X29: 0 | Y29: =G29*X29 -> 0
A30: 28 | B30: 46139 | C30: Gempol | D30: AJM | E30: Bpk M.Dhifi | F30: Jl. Rajawali II, Sidoarjo, 61273, ID(Warkop Nayenk) | G30: 11 | H30: K300 | I30: 790000 | J30: =I30*11% -> 86900 | K30: =I30+J30 -> 876900 | L30: =K30*G30 -> 9645900 | M30: 790000 | N30: =M30*11% -> 86900 | O30: =M30+N30 -> 876900 | P30: =O30*G30 -> 9645900 | Q30: 750000 | R30: =Q30*11% -> 82500 | S30: =Q30+R30 -> 832500 | T30: =S30*G30 -> 9157500 | U30: =(I30-M30)*G30 -> 0 | V30: =M30-Q30 -> 40000 | W30: =G30*V30 -> 440000 | X30: 0 | Y30: =G30*X30 -> 0
A31: 29 | B31: 46141 | C31: Gempol | D31: Cahyono | E31: Ibu Sari | F31: Rumah Istana Lokasi jln Ry kesiman- penanggungan pandaan | G31: 80 | H31: K300NFA | I31: =935000/1.11 -> 842342.34 | J31: =I31*11% -> 92657.658 | K31: =I31+J31 -> 935000 | L31: =K31*G31 -> 74800000 | M31: 835000 | N31: =M31*11% -> 91850 | O31: =M31+N31 -> 926850 | P31: =O31*G31 -> 74148000 | Q31: 775000 | R31: =Q31*11% -> 85250 | S31: =Q31+R31 -> 860250 | T31: =S31*G31 -> 68820000 | U31: =(I31-M31)*G31 -> 587387.39 | V31: =M31-Q31 -> 60000 | W31: =G31*V31 -> 4800000 | X31: 0 | Y31: =G31*X31 -> 0
A32: 30 | B32: 46141 | C32: Gempol | D32: AJM | E32: Bpk Erwin | F32: crusher wirabhumi sejati ngoro | G32: 15 | H32: K350 | I32: 850000 | J32: =I32*11% -> 93500 | K32: =I32+J32 -> 943500 | L32: =K32*G32 -> 14152500 | M32: 850000 | N32: =M32*11% -> 93500 | O32: =M32+N32 -> 943500 | P32: =O32*G32 -> 14152500 | Q32: 770000 | R32: =Q32*11% -> 84700 | S32: =Q32+R32 -> 854700 | T32: =S32*G32 -> 12820500 | U32: =(I32-M32)*G32 -> 0 | V32: =M32-Q32 -> 80000 | W32: =G32*V32 -> 1200000 | X32: 0 | Y32: =G32*X32 -> 0
A33: 31 | B33: 46142 | C33: Gempol | D33: AJM | E33: PT HP Metals Indonesia | F33: Ngoro Industri Persada Blok K No.2 Ngoro - Kabupaten Mojokerto | G33: 10 | H33: K350 | I33: 800000 | J33: =I33*11% -> 88000 | K33: =I33+J33 -> 888000 | L33: =K33*G33 -> 8880000 | M33: 800000 | N33: =M33*11% -> 88000 | O33: =M33+N33 -> 888000 | P33: =O33*G33 -> 8880000 | Q33: 750000 | R33: =Q33*11% -> 82500 | S33: =Q33+R33 -> 832500 | T33: =S33*G33 -> 8325000 | U33: =(I33-M33)*G33 -> 0 | V33: =M33-Q33 -> 50000 | W33: =G33*V33 -> 500000 | X33: 0 | Y33: =G33*X33 -> 0
A34: 32 | B34: 46142 | C34: Gempol | D34: AJM | E34: PT Solindo Tama Jaya | F34: Dn Gesing 0 RT 00 RW 00 randu pitu | G34: 46 | H34: K400 | I34: 850000 | J34: =I34*11% -> 93500 | K34: =I34+J34 -> 943500 | L34: =K34*G34 -> 43401000 | M34: 840000 | N34: =M34*11% -> 92400 | O34: =M34+N34 -> 932400 | P34: =O34*G34 -> 42890400 | Q34: 750000 | R34: =Q34*11% -> 82500 | S34: =Q34+R34 -> 832500 | T34: =S34*G34 -> 38295000 | U34: =(I34-M34)*G34 -> 460000 | V34: =M34-Q34 -> 90000 | W34: =G34*V34 -> 4140000 | X34: 0 | Y34: =G34*X34 -> 0
B37: TOTAL | G37: =SUM(G3:G36) -> 932.5 | L37: =SUM(L3:L36) -> 841723750 | P37: =SUM(P3:P36) -> 833233500 | T37: =SUM(T3:T36) -> 767800875 | U37: =SUM(U1:U32) -> 7188873.9 | W37: =SUM(W3:W36) -> 58948311 | X37: =W37/G37 -> 63215.347 | Y37: =SUM(Y35:Y36) -> 0

Sheet KEDIRI
A1: =MALANG!A1 -> REKAP PENJUALAN SALES AJM APRIL 2026
A2: NO | B2: DATE | C2: PLANT | D2: SALES | E2: CUSTOMER | F2: PROYEK | G2: VOL | H2: MUTU | I2: DEAL | J2: PPN | K2: HARGA + PPN | L2: TOTAL DEAL | M2: AJM | N2: PPN | O2: HARGA + PPN | P2: TOTAL AJM | Q2: BUY IN | R2: PPN | S2: HARGA + PPN | T2: TOTAL BUY IN | U2: FEE | V2: MARGIN/m3 | W2: TOTAL MARGIN | X2: SHARE MARGIN | Y2: TOTAL SHARE
A3: 1 | B3: 46113 | C3: Kediri | D3: Agus E | E3: NINDYA - SSPS KSO | F3: NINDYA - SSPS KSO | G3: 114 | H3: FC25 | I3: 780000 | J3: =I3*11% -> 85800 | K3: =I3+J3 -> 865800 | L3: =K3*G3 -> 98701200 | M3: 775000 | N3: =M3*11% -> 85250 | O3: =M3+N3 -> 860250 | P3: =O3*G3 -> 98068500 | Q3: 755000 | R3: =Q3*11% -> 83050 | S3: =Q3+R3 -> 838050 | T3: =S3*G3 -> 95537700 | U3: =G3*(I3-M3) -> 570000 | V3: =M3-Q3 -> 20000 | W3: =G3*V3 -> 2280000 | X3: 0 | Y3: =X3*G3 -> 0
A4: 2 | B4: 46113 | C4: Kediri | D4: Agus E | E4: Bp Pri | F4: Ds Pare Kediri | G4: 6 | H4: K300 Screening | I4: 780000 | J4: =I4*11% -> 85800 | K4: =I4+J4 -> 865800 | L4: =K4*G4 -> 5194800 | M4: 780000 | N4: =M4*11% -> 85800 | O4: =M4+N4 -> 865800 | P4: =O4*G4 -> 5194800 | Q4: 730000 | R4: =Q4*11% -> 80300 | S4: =Q4+R4 -> 810300 | T4: =S4*G4 -> 4861800 | U4: =G4*(I4-M4) -> 0 | V4: =M4-Q4 -> 50000 | W4: =G4*V4 -> 300000 | X4: 5000 | Y4: =X4*G4 -> 30000
A5: 3 | B5: 46114 | C5: Kediri | D5: Agus E | E5: Bp Pri | F5: Ds Pare Kediri | G5: 6 | H5: K300 Screening | I5: 780000 | J5: =I5*11% -> 85800 | K5: =I5+J5 -> 865800 | L5: =K5*G5 -> 5194800 | M5: 780000 | N5: =M5*11% -> 85800 | O5: =M5+N5 -> 865800 | P5: =O5*G5 -> 5194800 | Q5: 730000 | R5: =Q5*11% -> 80300 | S5: =Q5+R5 -> 810300 | T5: =S5*G5 -> 4861800 | U5: =G5*(I5-M5) -> 0 | V5: =M5-Q5 -> 50000 | W5: =G5*V5 -> 300000 | X5: 5000 | Y5: =X5*G5 -> 30000
A6: 4 | B6: 46114 | C6: Kediri | D6: Agus E | E6: NINDYA - SSPS KSO | F6: NINDYA - SSPS KSO | G6: 138 | H6: FC25 | I6: 780000 | J6: =I6*11% -> 85800 | K6: =I6+J6 -> 865800 | L6: =K6*G6 -> 119480400 | M6: 775000 | N6: =M6*11% -> 85250 | O6: =M6+N6 -> 860250 | P6: =O6*G6 -> 118714500 | Q6: 755000 | R6: =Q6*11% -> 83050 | S6: =Q6+R6 -> 838050 | T6: =S6*G6 -> 115650900 | U6: =G6*(I6-M6) -> 690000 | V6: =M6-Q6 -> 20000 | W6: =G6*V6 -> 2760000 | X6: 0 | Y6: =X6*G6 -> 0
A7: 5 | B7: 46116 | C7: Kediri | D7: Agus E | E7: NINDYA - SSPS KSO | F7: NINDYA - SSPS KSO | G7: 106 | H7: FC25 | I7: 780000 | J7: =I7*11% -> 85800 | K7: =I7+J7 -> 865800 | L7: =K7*G7 -> 91774800 | M7: 775000 | N7: =M7*11% -> 85250 | O7: =M7+N7 -> 860250 | P7: =O7*G7 -> 91186500 | Q7: 755000 | R7: =Q7*11% -> 83050 | S7: =Q7+R7 -> 838050 | T7: =S7*G7 -> 88833300 | U7: =G7*(I7-M7) -> 530000 | V7: =M7-Q7 -> 20000 | W7: =G7*V7 -> 2120000 | X7: 0 | Y7: =X7*G7 -> 0
A8: 6 | B8: 46116 | C8: Kediri | D8: Agus E | E8: Bp Pri | F8: Ds Pare Kediri | G8: 6 | H8: K300 Screening | I8: 780000 | J8: =I8*11% -> 85800 | K8: =I8+J8 -> 865800 | L8: =K8*G8 -> 5194800 | M8: 780000 | N8: =M8*11% -> 85800 | O8: =M8+N8 -> 865800 | P8: =O8*G8 -> 5194800 | Q8: 730000 | R8: =Q8*11% -> 80300 | S8: =Q8+R8 -> 810300 | T8: =S8*G8 -> 4861800 | U8: =G8*(I8-M8) -> 0 | V8: =M8-Q8 -> 50000 | W8: =G8*V8 -> 300000 | X8: 5000 | Y8: =X8*G8 -> 30000
A9: 7 | B9: 46116 | C9: Kediri | D9: Prapto | E9: Bapak Dimas | F9: Jl. Margotani Sukorame Mojoroto Kediri | G9: 30 | H9: K400 | I9: 790000 | J9: =I9*11% -> 86900 | K9: =I9+J9 -> 876900 | L9: =K9*G9 -> 26307000 | M9: 790000 | N9: =M9*11% -> 86900 | O9: =M9+N9 -> 876900 | P9: =O9*G9 -> 26307000 | Q9: 770000 | R9: =Q9*11% -> 84700 | S9: =Q9+R9 -> 854700 | T9: =S9*G9 -> 25641000 | U9: =G9*(I9-M9) -> 0 | V9: =M9-Q9 -> 20000 | W9: =G9*V9 -> 600000 | X9: 0 | Y9: =X9*G9 -> 0
A10: 8 | B10: 46118 | C10: Kediri | D10: Agus E | E10: Bp Pri | F10: Ds Pare Kediri | G10: 6 | H10: K300 Screening | I10: 780000 | J10: =I10*11% -> 85800 | K10: =I10+J10 -> 865800 | L10: =K10*G10 -> 5194800 | M10: 780000 | N10: =M10*11% -> 85800 | O10: =M10+N10 -> 865800 | P10: =O10*G10 -> 5194800 | Q10: 730000 | R10: =Q10*11% -> 80300 | S10: =Q10+R10 -> 810300 | T10: =S10*G10 -> 4861800 | U10: =G10*(I10-M10) -> 0 | V10: =M10-Q10 -> 50000 | W10: =G10*V10 -> 300000 | X10: 5000 | Y10: =X10*G10 -> 30000
A11: 9 | B11: 46118 | C11: Kediri | D11: Agus E | E11: Bp Pri | F11: Ds Pare Kediri | G11: 18 | H11: K300 | I11: 760000 | J11: =I11*11% -> 83600 | K11: =I11+J11 -> 843600 | L11: =K11*G11 -> 15184800 | M11: 760000 | N11: =M11*11% -> 83600 | O11: =M11+N11 -> 843600 | P11: =O11*G11 -> 15184800 | Q11: 710000 | R11: =Q11*11% -> 78100 | S11: =Q11+R11 -> 788100 | T11: =S11*G11 -> 14185800 | U11: 0 | V11: =M11-Q11 -> 50000 | W11: =G11*V11 -> 900000 | X11: 5000 | Y11: =X11*G11 -> 90000
A12: 10 | B12: 46119 | C12: Kediri | D12: Agus E | E12: Bp Pri | F12: Ds Pare Kediri | G12: 6 | H12: K300 Screening | I12: 780000 | J12: =I12*11% -> 85800 | K12: =I12+J12 -> 865800 | L12: =K12*G12 -> 5194800 | M12: 780000 | N12: =M12*11% -> 85800 | O12: =M12+N12 -> 865800 | P12: =O12*G12 -> 5194800 | Q12: 730000 | R12: =Q12*11% -> 80300 | S12: =Q12+R12 -> 810300 | T12: =S12*G12 -> 4861800 | U12: =G12*(I12-M12) -> 0 | V12: =M12-Q12 -> 50000 | W12: =G12*V12 -> 300000 | X12: 5000 | Y12: =X12*G12 -> 30000
A13: 11 | B13: 46120 | C13: Kediri | D13: Agus E | E13: Bp Pri | F13: Ds Pare Kediri | G13: 6 | H13: K300 Screening | I13: 780000 | J13: =I13*11% -> 85800 | K13: =I13+J13 -> 865800 | L13: =K13*G13 -> 5194800 | M13: 780000 | N13: =M13*11% -> 85800 | O13: =M13+N13 -> 865800 | P13: =O13*G13 -> 5194800 | Q13: 730000 | R13: =Q13*11% -> 80300 | S13: =Q13+R13 -> 810300 | T13: =S13*G13 -> 4861800 | U13: 0 | V13: =M13-Q13 -> 50000 | W13: =G13*V13 -> 300000 | X13: 5000 | Y13: =X13*G13 -> 30000
A14: 12 | B14: 46121 | C14: Kediri | D14: Agus E | E14: Bp Agus Karsono | F14: Jl Pamenang Katang Kediri | G14: 65 | H14: K300 | I14: 770000 | J14: =I14*11% -> 84700 | K14: =I14+J14 -> 854700 | L14: =K14*G14 -> 55555500 | M14: 770000 | N14: =M14*11% -> 84700 | O14: =M14+N14 -> 854700 | P14: =O14*G14 -> 55555500 | Q14: 720000 | R14: =Q14*11% -> 79200 | S14: =Q14+R14 -> 799200 | T14: =S14*G14 -> 51948000 | U14: =G14*(I14-M14) -> 0 | V14: =M14-Q14 -> 50000 | W14: =G14*V14 -> 3250000 | X14: 5000 | Y14: =X14*G14 -> 325000
A15: 13 | B15: 46122 | C15: Kediri | D15: Prapto | E15: Bpk. Anas | F15: Pondok Pesantren Lirboyo Kediri | G15: 6 | H15: K325 | I15: 790000 | J15: =I15*11% -> 86900 | K15: =I15+J15 -> 876900 | L15: =K15*G15 -> 5261400 | M15: 790000 | N15: =M15*11% -> 86900 | O15: =M15+N15 -> 876900 | P15: =O15*G15 -> 5261400 | Q15: 740000 | R15: =Q15*11% -> 81400 | S15: =Q15+R15 -> 821400 | T15: =S15*G15 -> 4928400 | U15: 0 | V15: =M15-Q15 -> 50000 | W15: =G15*V15 -> 300000 | X15: 15000 | Y15: =X15*G15 -> 90000
A16: 14 | B16: 46122 | C16: Kediri | D16: Agus E | E16: NINDYA - SSPS KSO | F16: NINDYA - SSPS KSO | G16: 60 | H16: FC25 | I16: 780000 | J16: =I16*11% -> 85800 | K16: =I16+J16 -> 865800 | L16: =K16*G16 -> 51948000 | M16: 775000 | N16: =M16*11% -> 85250 | O16: =M16+N16 -> 860250 | P16: =O16*G16 -> 51615000 | Q16: 755000 | R16: =Q16*11% -> 83050 | S16: =Q16+R16 -> 838050 | T16: =S16*G16 -> 50283000 | U16: 0 | V16: =M16-Q16 -> 20000 | W16: =G16*V16 -> 1200000 | X16: 0 | Y16: =X16*G16 -> 0
A17: 15 | B17: 46122 | C17: Kediri | D17: Agus E | E17: Bp Pri | F17: Ds Pare Kediri | G17: 6 | H17: K300 Screening | I17: 820000 | J17: =I17*11% -> 90200 | K17: =I17+J17 -> 910200 | L17: =K17*G17 -> 5461200 | M17: 820000 | N17: =M17*11% -> 90200 | O17: =M17+N17 -> 910200 | P17: =O17*G17 -> 5461200 | Q17: 784000 | R17: =Q17*11% -> 86240 | S17: =Q17+R17 -> 870240 | T17: =S17*G17 -> 5221440 | U17: 0 | V17: =M17-Q17 -> 36000 | W17: =G17*V17 -> 216000 | X17: 0 | Y17: =X17*G17 -> 0
A18: 16 | B18: 46123 | C18: Kediri | D18: Agus E | E18: NINDYA - SSPS KSO | F18: NINDYA - SSPS KSO | G18: 48 | H18: FC25 | I18: 780000 | J18: =I18*11% -> 85800 | K18: =I18+J18 -> 865800 | L18: =K18*G18 -> 41558400 | M18: 775000 | N18: =M18*11% -> 85250 | O18: =M18+N18 -> 860250 | P18: =O18*G18 -> 41292000 | Q18: 755000 | R18: =Q18*11% -> 83050 | S18: =Q18+R18 -> 838050 | T18: =S18*G18 -> 40226400 | U18: =G18*(I18-M18) -> 240000 | V18: =M18-Q18 -> 20000 | W18: =G18*V18 -> 960000 | X18: 0 | Y18: =X18*G18 -> 0
A19: 17 | B19: 46123 | C19: Kediri | D19: Agus E | E19: Bp Pri | F19: Ds Pare Kediri | G19: 6 | H19: K300 Screening | I19: 820000 | J19: =I19*11% -> 90200 | K19: =I19+J19 -> 910200 | L19: =K19*G19 -> 5461200 | M19: 820000 | N19: =M19*11% -> 90200 | O19: =M19+N19 -> 910200 | P19: =O19*G19 -> 5461200 | Q19: 784000 | R19: =Q19*11% -> 86240 | S19: =Q19+R19 -> 870240 | T19: =S19*G19 -> 5221440 | U19: =G19*(I19-M19) -> 0 | V19: =M19-Q19 -> 36000 | W19: =G19*V19 -> 216000 | X19: 0 | Y19: =X19*G19 -> 0
A20: 18 | B20: 46124 | C20: Kediri | D20: Prapto | E20: Bpk. Anas | F20: Pondok Pesantren Lirboyo Kediri | G20: 6 | H20: K325 | I20: 790000 | J20: =I20*11% -> 86900 | K20: =I20+J20 -> 876900 | L20: =K20*G20 -> 5261400 | M20: 790000 | N20: =M20*11% -> 86900 | O20: =M20+N20 -> 876900 | P20: =O20*G20 -> 5261400 | Q20: 740000 | R20: =Q20*11% -> 81400 | S20: =Q20+R20 -> 821400 | T20: =S20*G20 -> 4928400 | U20: =G20*(I20-M20) -> 0 | V20: =M20-Q20 -> 50000 | W20: =G20*V20 -> 300000 | X20: 15000 | Y20: =X20*G20 -> 90000
A21: 19 | B21: 46124 | C21: Kediri | D21: Agus E | E21: NINDYA - SSPS KSO | F21: NINDYA - SSPS KSO | G21: 114 | H21: FC25 | I21: 780000 | J21: =I21*11% -> 85800 | K21: =I21+J21 -> 865800 | L21: =K21*G21 -> 98701200 | M21: 775000 | N21: =M21*11% -> 85250 | O21: =M21+N21 -> 860250 | P21: =O21*G21 -> 98068500 | Q21: 755000 | R21: =Q21*11% -> 83050 | S21: =Q21+R21 -> 838050 | T21: =S21*G21 -> 95537700 | U21: =G21*(I21-M21) -> 570000 | V21: =M21-Q21 -> 20000 | W21: =G21*V21 -> 2280000 | X21: 0 | Y21: =X21*G21 -> 0
A22: 20 | B22: 46125 | C22: Kediri | D22: Agus E | E22: NINDYA - SSPS KSO | F22: NINDYA - SSPS KSO | G22: 48 | H22: FC25 | I22: 780000 | J22: =I22*11% -> 85800 | K22: =I22+J22 -> 865800 | L22: =K22*G22 -> 41558400 | M22: 775000 | N22: =M22*11% -> 85250 | O22: =M22+N22 -> 860250 | P22: =O22*G22 -> 41292000 | Q22: 755000 | R22: =Q22*11% -> 83050 | S22: =Q22+R22 -> 838050 | T22: =S22*G22 -> 40226400 | U22: 0 | V22: =M22-Q22 -> 20000 | W22: =G22*V22 -> 960000 | X22: 0 | Y22: =X22*G22 -> 0
A23: 21 | B23: 46125 | C23: Kediri | D23: Agus E | E23: Bp Pri | F23: Ds Pare Kediri | G23: 6 | H23: K300 Screening | I23: 820000 | J23: =I23*11% -> 90200 | K23: =I23+J23 -> 910200 | L23: =K23*G23 -> 5461200 | M23: 820000 | N23: =M23*11% -> 90200 | O23: =M23+N23 -> 910200 | P23: =O23*G23 -> 5461200 | Q23: 784000 | R23: =Q23*11% -> 86240 | S23: =Q23+R23 -> 870240 | T23: =S23*G23 -> 5221440 | U23: 0 | V23: =M23-Q23 -> 36000 | W23: =G23*V23 -> 216000 | X23: 0 | Y23: =X23*G23 -> 0
A24: 22 | B24: 46125 | C24: Kediri | D24: Prapto | E24: Ibu Paramita | F24: Ibu Paramita | G24: 11 | H24: K250 | I24: 745000 | J24: =I24*11% -> 81950 | K24: =I24+J24 -> 826950 | L24: =K24*G24 -> 9096450 | M24: 745000 | N24: =M24*11% -> 81950 | O24: =M24+N24 -> 826950 | P24: =O24*G24 -> 9096450 | Q24: 710000 | R24: =Q24*11% -> 78100 | S24: =Q24+R24 -> 788100 | T24: =S24*G24 -> 8669100 | U24: =G24*(I24-M24) -> 0 | V24: =M24-Q24 -> 35000 | W24: =G24*V24 -> 385000 | X24: 0 | Y24: =X24*G24 -> 0
A25: 23 | B25: 46125 | C25: Kediri | D25: Prapto | E25: Bapak Sutrisno | F25: Bapak Sutrisno | G25: 15.5 | H25: K250 | I25: 745000 | J25: =I25*11% -> 81950 | K25: =I25+J25 -> 826950 | L25: =K25*G25 -> 12817725 | M25: 745000 | N25: =M25*11% -> 81950 | O25: =M25+N25 -> 826950 | P25: =O25*G25 -> 12817725 | Q25: 710000 | R25: =Q25*11% -> 78100 | S25: =Q25+R25 -> 788100 | T25: =S25*G25 -> 12215550 | U25: =G25*(I25-M25) -> 0 | V25: =M25-Q25 -> 35000 | W25: =G25*V25 -> 542500 | X25: 0 | Y25: =X25*G25 -> 0
A26: 24 | B26: 46126 | C26: Kediri | D26: Prapto | E26: Bpk. Anas | F26: Pondok Pesantren Lirboyo Kediri | G26: 10 | H26: K325 | I26: 790000 | J26: =I26*11% -> 86900 | K26: =I26+J26 -> 876900 | L26: =K26*G26 -> 8769000 | M26: 790000 | N26: =M26*11% -> 86900 | O26: =M26+N26 -> 876900 | P26: =O26*G26 -> 8769000 | Q26: 740000 | R26: =Q26*11% -> 81400 | S26: =Q26+R26 -> 821400 | T26: =S26*G26 -> 8214000 | U26: 0 | V26: =M26-Q26 -> 50000 | W26: =G26*V26 -> 500000 | X26: 15000 | Y26: =X26*G26 -> 150000
A27: 25 | B27: 46126 | C27: Kediri | D27: Agus E | E27: NINDYA - SSPS KSO | F27: NINDYA - SSPS KSO | G27: 30 | H27: FC25 | I27: 780000 | J27: =I27*11% -> 85800 | K27: =I27+J27 -> 865800 | L27: =K27*G27 -> 25974000 | M27: 775000 | N27: =M27*11% -> 85250 | O27: =M27+N27 -> 860250 | P27: =O27*G27 -> 25807500 | Q27: 755000 | R27: =Q27*11% -> 83050 | S27: =Q27+R27 -> 838050 | T27: =S27*G27 -> 25141500 | U27: 0 | V27: =M27-Q27 -> 20000 | W27: =G27*V27 -> 600000 | X27: 0 | Y27: =X27*G27 -> 0
A28: 26 | B28: 46126 | C28: Kediri | D28: Agus E | E28: Bp Pri | F28: Ds Pare Kediri | G28: 6 | H28: K300 Screening | I28: 820000 | J28: =I28*11% -> 90200 | K28: =I28+J28 -> 910200 | L28: =K28*G28 -> 5461200 | M28: 820000 | N28: =M28*11% -> 90200 | O28: =M28+N28 -> 910200 | P28: =O28*G28 -> 5461200 | Q28: 784000 | R28: =Q28*11% -> 86240 | S28: =Q28+R28 -> 870240 | T28: =S28*G28 -> 5221440 | U28: =G28*(I28-M28) -> 0 | V28: =M28-Q28 -> 36000 | W28: =G28*V28 -> 216000 | X28: 0 | Y28: =X28*G28 -> 0
A29: 27 | B29: 46127 | C29: Kediri | D29: Agus E | E29: Bp Sasongko | F29: DS Bogo Kidul | G29: 4 | H29: K300 | I29: 800000 | J29: =I29*11% -> 88000 | K29: =I29+J29 -> 888000 | L29: =K29*G29 -> 3552000 | M29: 800000 | N29: =M29*11% -> 88000 | O29: =M29+N29 -> 888000 | P29: =O29*G29 -> 3552000 | Q29: 750000 | R29: =Q29*11% -> 82500 | S29: =Q29+R29 -> 832500 | T29: =S29*G29 -> 3330000 | U29: =G29*(I29-M29) -> 0 | V29: =M29-Q29 -> 50000 | W29: =G29*V29 -> 200000 | X29: 5000 | Y29: =X29*G29 -> 20000
A30: 28 | B30: 46127 | C30: Kediri | D30: Agus E | E30: Bp Pri | F30: Ds Pare Kediri | G30: 6 | H30: K300 Screening | I30: 820000 | J30: =I30*11% -> 90200 | K30: =I30+J30 -> 910200 | L30: =K30*G30 -> 5461200 | M30: 820000 | N30: =M30*11% -> 90200 | O30: =M30+N30 -> 910200 | P30: =O30*G30 -> 5461200 | Q30: 784000 | R30: =Q30*11% -> 86240 | S30: =Q30+R30 -> 870240 | T30: =S30*G30 -> 5221440 | U30: =G30*(I30-M30) -> 0 | V30: =M30-Q30 -> 36000 | W30: =G30*V30 -> 216000 | X30: 0 | Y30: =X30*G30 -> 0
A31: 29 | B31: 46129 | C31: Kediri | D31: Agus E | E31: Bp Pri | F31: Ds Pare Kediri | G31: 6 | H31: K300 Screening | I31: 890000 | J31: =I31*11% -> 97900 | K31: =I31+J31 -> 987900 | L31: =K31*G31 -> 5927400 | M31: 890000 | N31: =M31*11% -> 97900 | O31: =M31+N31 -> 987900 | P31: =O31*G31 -> 5927400 | Q31: 860000 | R31: =Q31*11% -> 94600 | S31: =Q31+R31 -> 954600 | T31: =S31*G31 -> 5727600 | U31: =G31*(I31-M31) -> 0 | V31: =M31-Q31 -> 30000 | W31: =G31*V31 -> 180000 | X31: 0 | Y31: =X31*G31 -> 0
A32: 30 | B32: 46129 | C32: Kediri | D32: Agus E | E32: Bp Drajat | F32: Jl. Putih Kec. Gampengrejo Kediri, Jawa Timur | G32: 30 | H32: K300 | I32: 820000 | J32: =I32*11% -> 90200 | K32: =I32+J32 -> 910200 | L32: =K32*G32 -> 27306000 | M32: 820000 | N32: =M32*11% -> 90200 | O32: =M32+N32 -> 910200 | P32: =O32*G32 -> 27306000 | Q32: 740000 | R32: =Q32*11% -> 81400 | S32: =Q32+R32 -> 821400 | T32: =S32*G32 -> 24642000 | U32: 0 | V32: =M32-Q32 -> 80000 | W32: =G32*V32 -> 2400000 | X32: 5000 | Y32: =X32*G32 -> 150000
A33: 31 | B33: 46129 | C33: Kediri | D33: Agus E | E33: Bp Drajat | F33: Jl. Putih Kec. Gampengrejo Kediri, Jawa Timur | G33: 90 | H33: K300NFA | I33: 820000 | J33: =I33*11% -> 90200 | K33: =I33+J33 -> 910200 | L33: =K33*G33 -> 81918000 | M33: 820000 | N33: =M33*11% -> 90200 | O33: =M33+N33 -> 910200 | P33: =O33*G33 -> 81918000 | Q33: 770000 | R33: =Q33*11% -> 84700 | S33: =Q33+R33 -> 854700 | T33: =S33*G33 -> 76923000 | U33: =G33*(I33-M33) -> 0 | V33: =M33-Q33 -> 50000 | W33: =G33*V33 -> 4500000 | X33: 5000 | Y33: =X33*G33 -> 450000
A34: 32 | B34: 46130 | C34: Kediri | D34: Prapto | E34: Bpk. Bin | F34: Tj Kalang Prambon Ngronggot Nganjuk | G34: 25 | H34: K300 | I34: 760000 | J34: =I34*11% -> 83600 | K34: =I34+J34 -> 843600 | L34: =K34*G34 -> 21090000 | M34: 760000 | N34: =M34*11% -> 83600 | O34: =M34+N34 -> 843600 | P34: =O34*G34 -> 21090000 | Q34: 725000 | R34: =Q34*11% -> 79750 | S34: =Q34+R34 -> 804750 | T34: =S34*G34 -> 20118750 | U34: =G34*(I34-M34) -> 0 | V34: =M34-Q34 -> 35000 | W34: =G34*V34 -> 875000 | X34: 0 | Y34: =X34*G34 -> 0
A35: 33 | B35: 46130 | C35: Kediri | D35: Agus E | E35: Bp Pri | F35: Ds Pare Kediri | G35: 6 | H35: K300 Screening | I35: 890000 | J35: =I35*11% -> 97900 | K35: =I35+J35 -> 987900 | L35: =K35*G35 -> 5927400 | M35: 890000 | N35: =M35*11% -> 97900 | O35: =M35+N35 -> 987900 | P35: =O35*G35 -> 5927400 | Q35: 860000 | R35: =Q35*11% -> 94600 | S35: =Q35+R35 -> 954600 | T35: =S35*G35 -> 5727600 | U35: =G35*(I35-M35) -> 0 | V35: =M35-Q35 -> 30000 | W35: =G35*V35 -> 180000 | X35: 0 | Y35: =X35*G35 -> 0
A36: 34 | B36: 46132 | C36: Kediri | D36: Agus E | E36: Bp Pri | F36: Ds Pare Kediri | G36: 6 | H36: K300 Screening | I36: 890000 | J36: =I36*11% -> 97900 | K36: =I36+J36 -> 987900 | L36: =K36*G36 -> 5927400 | M36: 890000 | N36: =M36*11% -> 97900 | O36: =M36+N36 -> 987900 | P36: =O36*G36 -> 5927400 | Q36: 860000 | R36: =Q36*11% -> 94600 | S36: =Q36+R36 -> 954600 | T36: =S36*G36 -> 5727600 | U36: =G36*(I36-M36) -> 0 | V36: =M36-Q36 -> 30000 | W36: =G36*V36 -> 180000 | X36: 0 | Y36: =X36*G36 -> 0
A37: 35 | B37: 46133 | C37: Kediri | D37: Prapto | E37: Bpk. Anas | F37: Pondok Pesantren Lirboyo Kediri | G37: 6 | H37: K325 | I37: 790000 | J37: =I37*11% -> 86900 | K37: =I37+J37 -> 876900 | L37: =K37*G37 -> 5261400 | M37: 790000 | N37: =M37*11% -> 86900 | O37: =M37+N37 -> 876900 | P37: =O37*G37 -> 5261400 | Q37: 740000 | R37: =Q37*11% -> 81400 | S37: =Q37+R37 -> 821400 | T37: =S37*G37 -> 4928400 | U37: 0 | V37: =M37-Q37 -> 50000 | W37: =G37*V37 -> 300000 | X37: 15000 | Y37: =X37*G37 -> 90000
A38: 36 | B38: 46135 | C38: Kediri | D38: Prapto | E38: Bpk. Anas | F38: Pondok Pesantren Lirboyo Kediri | G38: 6 | H38: K325 | I38: 790000 | J38: =I38*11% -> 86900 | K38: =I38+J38 -> 876900 | L38: =K38*G38 -> 5261400 | M38: 790000 | N38: =M38*11% -> 86900 | O38: =M38+N38 -> 876900 | P38: =O38*G38 -> 5261400 | Q38: 740000 | R38: =Q38*11% -> 81400 | S38: =Q38+R38 -> 821400 | T38: =S38*G38 -> 4928400 | U38: 0 | V38: =M38-Q38 -> 50000 | W38: =G38*V38 -> 300000 | X38: 15000 | Y38: =X38*G38 -> 90000
A39: 37 | B39: 46135 | C39: Kediri | D39: Prapto | E39: Desa Bangsongan | F39: Desa Bangsongan Kec. Kayen Kidul Kab. Kediri Peningkatan Jalan Desa Bangsongan Kab. Kediri | G39: 50 | H39: K300 | I39: 795000 | J39: =I39*11% -> 87450 | K39: =I39+J39 -> 882450 | L39: =K39*G39 -> 44122500 | M39: 780000 | N39: =M39*11% -> 85800 | O39: =M39+N39 -> 865800 | P39: =O39*G39 -> 43290000 | Q39: 730000 | R39: =Q39*11% -> 80300 | S39: =Q39+R39 -> 810300 | T39: =S39*G39 -> 40515000 | U39: 0 | V39: =M39-Q39 -> 50000 | W39: =G39*V39 -> 2500000 | X39: 15000 | Y39: =X39*G39 -> 750000
A40: 38 | B40: 46136 | C40: Kediri | D40: Agus E | E40: Bp Pri | F40: Ds Pare Kediri | G40: 6 | H40: K300 Screening | I40: 880000 | J40: =I40*11% -> 96800 | K40: =I40+J40 -> 976800 | L40: =K40*G40 -> 5860800 | M40: 880000 | N40: =M40*11% -> 96800 | O40: =M40+N40 -> 976800 | P40: =O40*G40 -> 5860800 | Q40: 860000 | R40: =Q40*11% -> 94600 | S40: =Q40+R40 -> 954600 | T40: =S40*G40 -> 5727600 | U40: 0 | V40: =M40-Q40 -> 20000 | W40: =G40*V40 -> 120000 | X40: 0 | Y40: =X40*G40 -> 0
...

Sheet MANUKAN
A1: =MALANG!A1 -> REKAP PENJUALAN SALES AJM APRIL 2026
A2: NO | B2: DATE | C2: PLANT | D2: SALES | E2: CUSTOMER | F2: PROYEK | G2: VOL | H2: MUTU | I2: DEAL | J2: PPN | K2: HARGA + PPN | L2: TOTAL DEAL | M2: AJM | N2: PPN | O2: HARGA + PPN | P2: TOTAL AJM | Q2: BUY IN | R2: PPN | S2: HARGA + PPN | T2: TOTAL BUY IN | U2: FEE | V2: MARGIN/m3 | W2: TOTAL MARGIN | X2: SHARE MARGIN | Y2: TOTAL SHARE
A3: 1 | B3: 46120 | C3: Manukan | D3: Reyza | E3: Bpk Budi | F3: margorejo indah blok b no 416 | G3: 2.5 | H3: K300 | I3: 800000 | J3: =I3*11% -> 88000 | K3: =I3+J3 -> 888000 | L3: =K3*G3 -> 2220000 | M3: 800000 | N3: =M3*11% -> 88000 | O3: =M3+N3 -> 888000 | P3: =O3*G3 -> 2220000 | Q3: 740000 | R3: =Q3*11% -> 81400 | S3: =Q3+R3 -> 821400 | T3: =S3*G3 -> 2053500 | U3: =G3*(I3-M3) -> 0 | V3: =M3-Q3 -> 60000 | W3: =G3*V3 -> 150000 | X3: 0 | Y3: =G3*X3 -> 0
A4: 2 | B4: 46123 | C4: Manukan | D4: AJM | E4: CV anugerah pratama mulia | F4: bumi marina emas utara blok f no 18b. Keputih, Kec. Sukolilo, Surabaya | G4: 19 | H4: K300 | I4: 800000 | J4: =I4*11% -> 88000 | K4: =I4+J4 -> 888000 | L4: =K4*G4 -> 16872000 | M4: 800000 | N4: =M4*11% -> 88000 | O4: =M4+N4 -> 888000 | P4: =O4*G4 -> 16872000 | Q4: 720000 | R4: =Q4*11% -> 79200 | S4: =Q4+R4 -> 799200 | T4: =S4*G4 -> 15184800 | U4: =G4*(I4-M4) -> 0 | V4: =M4-Q4 -> 80000 | W4: =G4*V4 -> 1520000 | X4: 0 | Y4: =G4*X4 -> 0
A5: 3 | B5: 46127 | C5: Manukan | D5: Rizal | E5: Pak Sunar | F5: Jl. Marina Emas Barat I No.30, Keputih, Kec. Sukolilo, Surabaya, Jawa Timur 60111 | G5: 24 | H5: K300 | I5: 780000 | J5: =I5*11% -> 85800 | K5: =I5+J5 -> 865800 | L5: =K5*G5 -> 20779200 | M5: 780000 | N5: =M5*11% -> 85800 | O5: =M5+N5 -> 865800 | P5: =O5*G5 -> 20779200 | Q5: 733000 | R5: =Q5*11% -> 80630 | S5: =Q5+R5 -> 813630 | T5: =S5*G5 -> 19527120 | U5: 0 | V5: =M5-Q5 -> 47000 | W5: =G5*V5 -> 1128000 | X5: 5000 | Y5: =G5*X5 -> 120000
A6: 4 | B6: 46140 | C6: Manukan | D6: Rizal | E6: Bapak Fredy | F6: Jl. Pregolan Bunder No. 15 RT. 02/RW. 02 Tegalsari Surabaya | G6: 6.5 | H6: K225 | I6: =920000/1.11 -> 828828.83 | J6: =I6*11% -> 91171.171 | K6: =I6+J6 -> 920000 | L6: =K6*G6 -> 5980000 | M6: =920000/1.11 -> 828828.83 | N6: =M6*11% -> 91171.171 | O6: =M6+N6 -> 920000 | P6: =O6*G6 -> 5980000 | Q6: 690000 | R6: =Q6*11% -> 75900 | S6: =Q6+R6 -> 765900 | T6: =S6*G6 -> 4978350 | U6: =G6*(I6-M6) -> 0 | V6: =M6-Q6 -> 138828.83 | W6: =G6*V6 -> 902387.39 | X6: 5000 | Y6: =G6*X6 -> 32500
A7: 5 | B7: 46142 | C7: Manukan | D7: AJM | E7: Gema Putra Perkasa (Eni) | F7: Dukuh kupang timur VII No 17 A | G7: 18 | H7: K225 | I7: =970000/1.11 -> 873873.87 | J7: =I7*11% -> 96126.126 | K7: =I7+J7 -> 970000 | L7: =K7*G7 -> 17460000 | M7: 700000 | N7: =M7*11% -> 77000 | O7: =M7+N7 -> 777000 | P7: =O7*G7 -> 13986000 | Q7: 675000 | R7: =Q7*11% -> 74250 | S7: =Q7+R7 -> 749250 | T7: =S7*G7 -> 13486500 | U7: =G7*(I7-M7) -> 3129729.7 | V7: =M7-Q7 -> 25000 | W7: =G7*V7 -> 450000 | X7: 0 | Y7: =G7*X7 -> 0
A8: 6 | B8: 46142 | C8: Manukan | D8: Rizal | E8: PT Lintang karya sampurna | F8: PT PAL Surabaya,Jalan Ujung, Ujung, Kec. Semampir, Surabaya, Jawa Timur 60155 | G8: 38 | H8: K350 | I8: 850000 | J8: =I8*11% -> 93500 | K8: =I8+J8 -> 943500 | L8: =K8*G8 -> 35853000 | M8: 850000 | N8: =M8*11% -> 93500 | O8: =M8+N8 -> 943500 | P8: =O8*G8 -> 35853000 | Q8: 770000 | R8: =Q8*11% -> 84700 | S8: =Q8+R8 -> 854700 | T8: =S8*G8 -> 32478600 | U8: =G8*(I8-M8) -> 0 | V8: =M8-Q8 -> 80000 | W8: =G8*V8 -> 3040000 | X8: 5000 | Y8: =G8*X8 -> 190000
A9: 7 | C9: Manukan | J9: =I9*11% -> 0 | K9: =I9+J9 -> 0 | L9: =K9*G9 -> 0 | N9: =M9*11% -> 0 | O9: =M9+N9 -> 0 | P9: =O9*G9 -> 0 | R9: =Q9*11% -> 0 | S9: =Q9+R9 -> 0 | T9: =S9*G9 -> 0 | U9: =G9*(I9-M9) -> 0 | V9: =M9-Q9 -> 0 | W9: =G9*V9 -> 0 | X9: 0 | Y9: =G9*X9 -> 0
A10: 8 | C10: Manukan | J10: =I10*11% -> 0 | K10: =I10+J10 -> 0 | L10: =K10*G10 -> 0 | N10: =M10*11% -> 0 | O10: =M10+N10 -> 0 | P10: =O10*G10 -> 0 | R10: =Q10*11% -> 0 | S10: =Q10+R10 -> 0 | T10: =S10*G10 -> 0 | U10: =G10*(I10-M10) -> 0 | V10: =M10-Q10 -> 0 | W10: =G10*V10 -> 0 | X10: 0 | Y10: =G10*X10 -> 0
A11: 9 | C11: Manukan | J11: =I11*11% -> 0 | K11: =I11+J11 -> 0 | L11: =K11*G11 -> 0 | N11: =M11*11% -> 0 | O11: =M11+N11 -> 0 | P11: =O11*G11 -> 0 | R11: =Q11*11% -> 0 | S11: =Q11+R11 -> 0 | T11: =S11*G11 -> 0 | U11: =G11*(I11-M11) -> 0 | V11: =M11-Q11 -> 0 | W11: =G11*V11 -> 0 | X11: 0 | Y11: =G11*X11 -> 0
A12: 10 | C12: Manukan | J12: =I12*11% -> 0 | K12: =I12+J12 -> 0 | L12: =K12*G12 -> 0 | N12: =M12*11% -> 0 | O12: =M12+N12 -> 0 | P12: =O12*G12 -> 0 | R12: =Q12*11% -> 0 | S12: =Q12+R12 -> 0 | T12: =S12*G12 -> 0 | U12: =G12*(I12-M12) -> 0 | V12: =M12-Q12 -> 0 | W12: =G12*V12 -> 0 | X12: 0 | Y12: =G12*X12 -> 0
A13: 11 | C13: Manukan | J13: =I13*11% -> 0 | K13: =I13+J13 -> 0 | L13: =K13*G13 -> 0 | N13: =M13*11% -> 0 | O13: =M13+N13 -> 0 | P13: =O13*G13 -> 0 | R13: =Q13*11% -> 0 | S13: =Q13+R13 -> 0 | T13: =S13*G13 -> 0 | U13: =G13*(I13-M13) -> 0 | V13: =M13-Q13 -> 0 | W13: =G13*V13 -> 0 | X13: 0 | Y13: =G13*X13 -> 0
A14: 12 | C14: Manukan | J14: =I14*11% -> 0 | K14: =I14+J14 -> 0 | L14: =K14*G14 -> 0 | N14: =M14*11% -> 0 | O14: =M14+N14 -> 0 | P14: =O14*G14 -> 0 | R14: =Q14*11% -> 0 | S14: =Q14+R14 -> 0 | T14: =S14*G14 -> 0 | U14: =G14*(I14-M14) -> 0 | V14: =M14-Q14 -> 0 | W14: =G14*V14 -> 0 | X14: 0 | Y14: =G14*X14 -> 0
A15: 13 | C15: Manukan | J15: =I15*11% -> 0 | K15: =I15+J15 -> 0 | L15: =K15*G15 -> 0 | N15: =M15*11% -> 0 | O15: =M15+N15 -> 0 | P15: =O15*G15 -> 0 | R15: =Q15*11% -> 0 | S15: =Q15+R15 -> 0 | T15: =S15*G15 -> 0 | U15: =G15*(I15-M15) -> 0 | V15: =M15-Q15 -> 0 | W15: =G15*V15 -> 0 | X15: 0 | Y15: =G15*X15 -> 0
A16: 14 | C16: Manukan | J16: =I16*11% -> 0 | K16: =I16+J16 -> 0 | L16: =K16*G16 -> 0 | N16: =M16*11% -> 0 | O16: =M16+N16 -> 0 | P16: =O16*G16 -> 0 | R16: =Q16*11% -> 0 | S16: =Q16+R16 -> 0 | T16: =S16*G16 -> 0 | U16: =G16*(I16-M16) -> 0 | V16: =M16-Q16 -> 0 | W16: =G16*V16 -> 0 | X16: 0 | Y16: =G16*X16 -> 0
A17: 15 | C17: Manukan | J17: =I17*11% -> 0 | K17: =I17+J17 -> 0 | L17: =K17*G17 -> 0 | N17: =M17*11% -> 0 | O17: =M17+N17 -> 0 | P17: =O17*G17 -> 0 | R17: =Q17*11% -> 0 | S17: =Q17+R17 -> 0 | T17: =S17*G17 -> 0 | U17: =G17*(I17-M17) -> 0 | V17: =M17-Q17 -> 0 | W17: =G17*V17 -> 0 | X17: 0 | Y17: =G17*X17 -> 0
A18: 16 | C18: Manukan | J18: =I18*11% -> 0 | K18: =I18+J18 -> 0 | L18: =K18*G18 -> 0 | N18: =M18*11% -> 0 | O18: =M18+N18 -> 0 | P18: =O18*G18 -> 0 | R18: =Q18*11% -> 0 | S18: =Q18+R18 -> 0 | T18: =S18*G18 -> 0 | U18: 0 | V18: =M18-Q18 -> 0 | W18: =G18*V18 -> 0 | X18: 0 | Y18: =G18*X18 -> 0
A19: 17 | C19: Manukan | J19: =I19*11% -> 0 | K19: =I19+J19 -> 0 | L19: =K19*G19 -> 0 | N19: =M19*11% -> 0 | O19: =M19+N19 -> 0 | P19: =O19*G19 -> 0 | R19: =Q19*11% -> 0 | S19: =Q19+R19 -> 0 | T19: =S19*G19 -> 0 | U19: =G19*(I19-M19) -> 0 | V19: =M19-Q19 -> 0 | W19: =G19*V19 -> 0 | X19: 0 | Y19: =G19*X19 -> 0
A20: 18 | C20: Manukan | J20: =I20*11% -> 0 | K20: =I20+J20 -> 0 | L20: =K20*G20 -> 0 | N20: =M20*11% -> 0 | O20: =M20+N20 -> 0 | P20: =O20*G20 -> 0 | R20: =Q20*11% -> 0 | S20: =Q20+R20 -> 0 | T20: =S20*G20 -> 0 | U20: =G20*(I20-M20) -> 0 | V20: =M20-Q20 -> 0 | W20: =G20*V20 -> 0 | X20: 0 | Y20: =G20*X20 -> 0
A21: 19 | C21: Manukan | J21: =I21*11% -> 0 | K21: =I21+J21 -> 0 | L21: =K21*G21 -> 0 | N21: =M21*11% -> 0 | O21: =M21+N21 -> 0 | P21: =O21*G21 -> 0 | R21: =Q21*11% -> 0 | S21: =Q21+R21 -> 0 | T21: =S21*G21 -> 0 | U21: =G21*(I21-M21) -> 0 | V21: =M21-Q21 -> 0 | W21: =G21*V21 -> 0 | X21: 0 | Y21: =G21*X21 -> 0
A22: 20 | C22: Manukan | J22: =I22*11% -> 0 | K22: =I22+J22 -> 0 | L22: =K22*G22 -> 0 | N22: =M22*11% -> 0 | O22: =M22+N22 -> 0 | P22: =O22*G22 -> 0 | R22: =Q22*11% -> 0 | S22: =Q22+R22 -> 0 | T22: =S22*G22 -> 0 | U22: =G22*(I22-M22) -> 0 | V22: =M22-Q22 -> 0 | W22: =G22*V22 -> 0 | X22: 0 | Y22: =G22*X22 -> 0
B25: TOTAL | G25: =SUBTOTAL(9,G3:G24) -> 37 | L25: =SUM(L3:L24) -> 99164200 | P25: =SUM(P3:P24) -> 95690200 | T25: =SUM(T3:T24) -> 87708870 | U25: =SUM(U3:U24) -> 3129729.7 | W25: =SUM(W3:W24) -> 7190387.4 | X25: =W25/G25 -> 194334.79 | Y25: =SUM(Y3:Y24) -> 342500

Sheet PLANT LAIN-LAIN
A1: =MALANG!A1 -> REKAP PENJUALAN SALES AJM APRIL 2026
A2: NO | B2: DATE | C2: PLANT | D2: SALES | E2: CUSTOMER | F2: PROYEK | G2: VOL | H2: MUTU | I2: DEAL | J2: PPN | K2: HARGA + PPN | L2: TOTAL DEAL | M2: AJM | N2: PPN | O2: HARGA + PPN | P2: TOTAL AJM | Q2: BUY IN | R2: PPN | S2: HARGA + PPN | T2: TOTAL BUY IN | U2: FEE | V2: MARGIN/m3 | W2: TOTAL MARGIN | X2: SHARE MARGIN | Y2: TOTAL SHARE
A3: 1 | B3: 46113 | C3: Jakarta | D3: Agus | E3: PT KAUSYAR RIZKI LESTARI | F3: RS. Setia Mitra - Jakarta Selatan | G3: 6 | H3: K-300 SP 7 | I3: 1520000 | J3: =I3*11% -> 167200 | K3: =I3+J3 -> 1687200 | L3: =K3*G3 -> 10123200 | M3: 1350000 | N3: =M3*11% -> 148500 | O3: =M3+N3 -> 1498500 | P3: =O3*G3 -> 8991000 | Q3: 1200000 | R3: =Q3*11% -> 132000 | S3: =Q3+R3 -> 1332000 | T3: =S3*G3 -> 7992000 | U3: 0 | V3: =M3-Q3 -> 150000 | W3: =G3*V3 -> 900000 | X3: 5000 | Y3: =G3*X3 -> 30000
A4: 2 | B4: 46114 | C4: Jakarta | D4: Agus | E4: PT KAUSYAR RIZKI LESTARI | F4: RS. Setia Mitra - Jakarta Selatan | G4: 8 | H4: K-300 SP 7 | I4: 1520000 | J4: =I4*11% -> 167200 | K4: =I4+J4 -> 1687200 | L4: =K4*G4 -> 13497600 | M4: 1350000 | N4: =M4*11% -> 148500 | O4: =M4+N4 -> 1498500 | P4: =O4*G4 -> 11988000 | Q4: 1200000 | R4: =Q4*11% -> 132000 | S4: =Q4+R4 -> 1332000 | T4: =S4*G4 -> 10656000 | U4: 0 | V4: =M4-Q4 -> 150000 | W4: =G4*V4 -> 1200000 | X4: 5000 | Y4: =G4*X4 -> 40000
A5: 3 | B5: 46118 | C5: Jakarta | D5: Agus | E5: PT KAUSYAR RIZKI LESTARI | F5: RS. Setia Mitra - Jakarta Selatan | G5: 7 | H5: K-300 SP 14 | I5: 1380000 | J5: =I5*11% -> 151800 | K5: =I5+J5 -> 1531800 | L5: =K5*G5 -> 10722600 | M5: 1250000 | N5: =M5*11% -> 137500 | O5: =M5+N5 -> 1387500 | P5: =O5*G5 -> 9712500 | Q5: 1150000 | R5: =Q5*11% -> 126500 | S5: =Q5+R5 -> 1276500 | T5: =S5*G5 -> 8935500 | U5: 0 | V5: =M5-Q5 -> 100000 | W5: =G5*V5 -> 700000 | X5: 5000 | Y5: =G5*X5 -> 35000
A6: 4 | B6: 46122 | C6: Jakarta | D6: Agus | E6: PT KAUSYAR RIZKI LESTARI | F6: RS. Setia Mitra - Jakarta Selatan | G6: 7 | H6: K-300 SP 7 | I6: 1520000 | J6: =I6*11% -> 167200 | K6: =I6+J6 -> 1687200 | L6: =K6*G6 -> 11810400 | M6: 1350000 | N6: =M6*11% -> 148500 | O6: =M6+N6 -> 1498500 | P6: =O6*G6 -> 10489500 | Q6: 1200000 | R6: =Q6*11% -> 132000 | S6: =Q6+R6 -> 1332000 | T6: =S6*G6 -> 9324000 | U6: 0 | V6: =M6-Q6 -> 150000 | W6: =G6*V6 -> 1050000 | X6: 5000 | Y6: =G6*X6 -> 35000
A7: 5 | B7: 46125 | C7: Jakarta | D7: Agus | E7: PT KAUSYAR RIZKI LESTARI | F7: RS. Setia Mitra - Jakarta Selatan | G7: 5 | H7: K-300 SP 3 | I7: 1600000 | J7: =I7*11% -> 176000 | K7: =I7+J7 -> 1776000 | L7: =K7*G7 -> 8880000 | M7: 1500000 | N7: =M7*11% -> 165000 | O7: =M7+N7 -> 1665000 | P7: =O7*G7 -> 8325000 | Q7: 1400000 | R7: =Q7*11% -> 154000 | S7: =Q7+R7 -> 1554000 | T7: =S7*G7 -> 7770000 | U7: 0 | V7: =M7-Q7 -> 100000 | W7: =G7*V7 -> 500000 | X7: 5000 | Y7: =G7*X7 -> 25000
A8: 6 | B8: 46125 | C8: Jakarta | D8: Agus | E8: PT KAUSYAR RIZKI LESTARI | F8: RS. Setia Mitra - Jakarta Selatan | G8: 11 | H8: K-300 SP 7 | I8: 1520000 | J8: =I8*11% -> 167200 | K8: =I8+J8 -> 1687200 | L8: =K8*G8 -> 18559200 | M8: 1350000 | N8: =M8*11% -> 148500 | O8: =M8+N8 -> 1498500 | P8: =O8*G8 -> 16483500 | Q8: 1200000 | R8: =Q8*11% -> 132000 | S8: =Q8+R8 -> 1332000 | T8: =S8*G8 -> 14652000 | U8: 0 | V8: =M8-Q8 -> 150000 | W8: =G8*V8 -> 1650000 | X8: 5000 | Y8: =G8*X8 -> 55000
A9: 7 | B9: 46127 | C9: Jakarta | D9: Agus | E9: PT KAUSYAR RIZKI LESTARI | F9: RS. Setia Mitra - Jakarta Selatan | G9: 7 | H9: K-300 SP 7 | I9: 1520000 | J9: =I9*11% -> 167200 | K9: =I9+J9 -> 1687200 | L9: =K9*G9 -> 11810400 | M9: 1350000 | N9: =M9*11% -> 148500 | O9: =M9+N9 -> 1498500 | P9: =O9*G9 -> 10489500 | Q9: 1200000 | R9: =Q9*11% -> 132000 | S9: =Q9+R9 -> 1332000 | T9: =S9*G9 -> 9324000 | U9: 0 | V9: =M9-Q9 -> 150000 | W9: =G9*V9 -> 1050000 | X9: 5000 | Y9: =G9*X9 -> 35000
A10: 8 | B10: 46128 | C10: Jakarta | D10: Agus | E10: PT KAUSYAR RIZKI LESTARI | F10: RS. Setia Mitra - Jakarta Selatan | G10: 7 | H10: K-300 SP 7 | I10: 1520000 | J10: =I10*11% -> 167200 | K10: =I10+J10 -> 1687200 | L10: =K10*G10 -> 11810400 | M10: 1350000 | N10: =M10*11% -> 148500 | O10: =M10+N10 -> 1498500 | P10: =O10*G10 -> 10489500 | Q10: 1200000 | R10: =Q10*11% -> 132000 | S10: =Q10+R10 -> 1332000 | T10: =S10*G10 -> 9324000 | U10: 0 | V10: =M10-Q10 -> 150000 | W10: =G10*V10 -> 1050000 | X10: 5000 | Y10: =G10*X10 -> 35000
A11: 9 | B11: 46127 | C11: Solo Ring Road | D11: Agus | E11: PROYEK RUMAH KOS | F11: JL MELON RAYA KARANGASEM SOLO | G11: 30 | H11: K300NFA | I11: 940000 | J11: =I11*11% -> 103400 | K11: =I11+J11 -> 1043400 | L11: =K11*G11 -> 31302000 | M11: 875000 | N11: =M11*11% -> 96250 | O11: =M11+N11 -> 971250 | P11: =O11*G11 -> 29137500 | Q11: 790000 | R11: =Q11*11% -> 86900 | S11: =Q11+R11 -> 876900 | T11: =S11*G11 -> 26307000 | U11: 0 | V11: =M11-Q11 -> 85000 | W11: =G11*V11 -> 2550000 | X11: 5000 | Y11: =G11*X11 -> 150000
A12: 10 | B12: 46133 | C12: Gempol | D12: Rizal | E12: PT Tri Megah Baswara | F12: PT Tri Megah Baswara | G12: 250 | H12: CNP | I12: 536036 | J12: =I12*11% -> 58963.96 | K12: =I12+J12 -> 594999.96 | L12: =K12*G12 -> 148749990 | M12: 450000 | N12: =M12*11% -> 49500 | O12: =M12+N12 -> 499500 | P12: =O12*G12 -> 124875000 | Q12: =470000/1.11 -> 423423.42 | R12: =Q12*11% -> 46576.577 | S12: =Q12+R12 -> 470000 | T12: =S12*G12 -> 1.175e+08 | U12: =(I12-M12)*G12 -> 21509000 | V12: =M12-Q12 -> 26576.577 | W12: =G12*V12 -> 6644144.1 | X12: 5000 | Y12: =G12*X12 -> 1250000
A13: 11 | B13: 46133 | C13: Gempol | D13: Rizal | E13: PT Tri Megah Baswara | F13: PT Tri Megah Baswara | G13: 20 | H13: CNP | I13: 536036 | J13: =I13*11% -> 58963.96 | K13: =I13+J13 -> 594999.96 | L13: =K13*G13 -> 11899999 | M13: 370000 | N13: =M13*11% -> 40700 | O13: =M13+N13 -> 410700 | P13: =O13*G13 -> 8214000 | Q13: =380000/1.11 -> 342342.34 | R13: =Q13*11% -> 37657.658 | S13: =Q13+R13 -> 380000 | T13: =S13*G13 -> 7600000 | U13: =(I13-M13)*G13 -> 3320720 | V13: =M13-Q13 -> 27657.658 | W13: =G13*V13 -> 553153.15 | X13: 5000 | Y13: =G13*X13 -> 100000
A14: 12 | J14: =I14*11% -> 0 | K14: =I14+J14 -> 0 | L14: =K14*G14 -> 0 | N14: =M14*11% -> 0 | O14: =M14+N14 -> 0 | P14: =O14*G14 -> 0 | R14: =Q14*11% -> 0 | S14: =Q14+R14 -> 0 | T14: =S14*G14 -> 0 | U14: 0 | V14: =M14-Q14 -> 0 | W14: =G14*V14 -> 0 | X14: 0 | Y14: =G14*X14 -> 0
A15: 13 | J15: =I15*11% -> 0 | K15: =I15+J15 -> 0 | L15: =K15*G15 -> 0 | N15: =M15*11% -> 0 | O15: =M15+N15 -> 0 | P15: =O15*G15 -> 0 | R15: =Q15*11% -> 0 | S15: =Q15+R15 -> 0 | T15: =S15*G15 -> 0 | U15: 0 | V15: =M15-Q15 -> 0 | W15: =G15*V15 -> 0 | X15: 0 | Y15: =G15*X15 -> 0
A16: 14 | J16: =I16*11% -> 0 | K16: =I16+J16 -> 0 | L16: =K16*G16 -> 0 | N16: =M16*11% -> 0 | O16: =M16+N16 -> 0 | P16: =O16*G16 -> 0 | R16: =Q16*11% -> 0 | S16: =Q16+R16 -> 0 | T16: =S16*G16 -> 0 | U16: =G16*(I16-M16) -> 0 | V16: =M16-Q16 -> 0 | W16: =G16*V16 -> 0 | X16: 0 | Y16: =G16*X16 -> 0
A17: 15 | J17: =I17*11% -> 0 | K17: =I17+J17 -> 0 | L17: =K17*G17 -> 0 | N17: =M17*11% -> 0 | O17: =M17+N17 -> 0 | P17: =O17*G17 -> 0 | R17: =Q17*11% -> 0 | S17: =Q17+R17 -> 0 | T17: =S17*G17 -> 0 | U17: =G17*(I17-M17) -> 0 | V17: =M17-Q17 -> 0 | W17: =G17*V17 -> 0 | X17: 0 | Y17: =G17*X17 -> 0
A18: 16 | J18: =I18*11% -> 0 | K18: =I18+J18 -> 0 | L18: =K18*G18 -> 0 | N18: =M18*11% -> 0 | O18: =M18+N18 -> 0 | P18: =O18*G18 -> 0 | R18: =Q18*11% -> 0 | S18: =Q18+R18 -> 0 | T18: =S18*G18 -> 0 | U18: =G18*(I18-M18) -> 0 | V18: =M18-Q18 -> 0 | W18: =G18*V18 -> 0 | X18: 0 | Y18: =G18*X18 -> 0
A19: 17 | J19: =I19*11% -> 0 | K19: =I19+J19 -> 0 | L19: =K19*G19 -> 0 | N19: =M19*11% -> 0 | O19: =M19+N19 -> 0 | P19: =O19*G19 -> 0 | R19: =Q19*11% -> 0 | S19: =Q19+R19 -> 0 | T19: =S19*G19 -> 0 | U19: =G19*(I19-M19) -> 0 | V19: =M19-Q19 -> 0 | W19: =G19*V19 -> 0 | X19: 0 | Y19: =G19*X19 -> 0
A20: 18 | J20: =I20*11% -> 0 | K20: =I20+J20 -> 0 | L20: =K20*G20 -> 0 | N20: =M20*11% -> 0 | O20: =M20+N20 -> 0 | P20: =O20*G20 -> 0 | R20: =Q20*11% -> 0 | S20: =Q20+R20 -> 0 | T20: =S20*G20 -> 0 | U20: =G20*(I20-M20) -> 0 | V20: =M20-Q20 -> 0 | W20: =G20*V20 -> 0 | X20: 0 | Y20: =G20*X20 -> 0
A21: 19 | J21: =I21*11% -> 0 | K21: =I21+J21 -> 0 | L21: =K21*G21 -> 0 | N21: =M21*11% -> 0 | O21: =M21+N21 -> 0 | P21: =O21*G21 -> 0 | R21: =Q21*11% -> 0 | S21: =Q21+R21 -> 0 | T21: =S21*G21 -> 0 | U21: =G21*(I21-M21) -> 0 | V21: =M21-Q21 -> 0 | W21: =G21*V21 -> 0 | X21: 0 | Y21: =G21*X21 -> 0
A22: 20 | J22: =I22*11% -> 0 | K22: =I22+J22 -> 0 | L22: =K22*G22 -> 0 | N22: =M22*11% -> 0 | O22: =M22+N22 -> 0 | P22: =O22*G22 -> 0 | R22: =Q22*11% -> 0 | S22: =Q22+R22 -> 0 | T22: =S22*G22 -> 0 | U22: =G22*(I22-M22) -> 0 | V22: =M22-Q22 -> 0 | W22: =G22*V22 -> 0 | X22: 0 | Y22: =G22*X22 -> 0
A23: 21 | J23: =I23*11% -> 0 | K23: =I23+J23 -> 0 | L23: =K23*G23 -> 0 | N23: =M23*11% -> 0 | O23: =M23+N23 -> 0 | P23: =O23*G23 -> 0 | R23: =Q23*11% -> 0 | S23: =Q23+R23 -> 0 | T23: =S23*G23 -> 0 | U23: =G23*(I23-M23) -> 0 | V23: =M23-Q23 -> 0 | W23: =G23*V23 -> 0 | X23: 0 | Y23: =G23*X23 -> 0
A24: 22 | J24: =I24*11% -> 0 | K24: =I24+J24 -> 0 | L24: =K24*G24 -> 0 | N24: =M24*11% -> 0 | O24: =M24+N24 -> 0 | P24: =O24*G24 -> 0 | R24: =Q24*11% -> 0 | S24: =Q24+R24 -> 0 | T24: =S24*G24 -> 0 | U24: =G24*(I24-M24) -> 0 | V24: =M24-Q24 -> 0 | W24: =G24*V24 -> 0 | X24: 0 | Y24: =G24*X24 -> 0
B27: TOTAL | G27: =SUM(G3:G26) -> 358 | L27: =SUM(L3:L26) -> 2.8916579e+08 | P27: =SUM(P3:P26) -> 249195000 | T27: =SUM(T3:T26) -> 229384500 | U27: =SUM(U3:U26) -> 24829720 | W27: =SUM(W3:W26) -> 17847297 | X27: =W27/G27 -> 49852.786 | Y27: =SUM(Y3:Y26) -> 1790000
